{
 "cells": [
  {
   "cell_type": "code",
   "execution_count": 12,
   "id": "971b6c05",
   "metadata": {},
   "outputs": [],
   "source": [
    "import pandas as pd\n",
    "df = pd.read_csv('yelp_labelled.txt', names=['sentence', 'label'], sep='\\t')"
   ]
  },
  {
   "cell_type": "code",
   "execution_count": 13,
   "id": "a96c4587",
   "metadata": {},
   "outputs": [
    {
     "data": {
      "text/html": [
       "<div>\n",
       "<style scoped>\n",
       "    .dataframe tbody tr th:only-of-type {\n",
       "        vertical-align: middle;\n",
       "    }\n",
       "\n",
       "    .dataframe tbody tr th {\n",
       "        vertical-align: top;\n",
       "    }\n",
       "\n",
       "    .dataframe thead th {\n",
       "        text-align: right;\n",
       "    }\n",
       "</style>\n",
       "<table border=\"1\" class=\"dataframe\">\n",
       "  <thead>\n",
       "    <tr style=\"text-align: right;\">\n",
       "      <th></th>\n",
       "      <th>sentence</th>\n",
       "      <th>label</th>\n",
       "    </tr>\n",
       "  </thead>\n",
       "  <tbody>\n",
       "    <tr>\n",
       "      <th>995</th>\n",
       "      <td>I think food should have flavor and texture an...</td>\n",
       "      <td>0</td>\n",
       "    </tr>\n",
       "    <tr>\n",
       "      <th>996</th>\n",
       "      <td>Appetite instantly gone.</td>\n",
       "      <td>0</td>\n",
       "    </tr>\n",
       "    <tr>\n",
       "      <th>997</th>\n",
       "      <td>Overall I was not impressed and would not go b...</td>\n",
       "      <td>0</td>\n",
       "    </tr>\n",
       "    <tr>\n",
       "      <th>998</th>\n",
       "      <td>The whole experience was underwhelming, and I ...</td>\n",
       "      <td>0</td>\n",
       "    </tr>\n",
       "    <tr>\n",
       "      <th>999</th>\n",
       "      <td>Then, as if I hadn't wasted enough of my life ...</td>\n",
       "      <td>0</td>\n",
       "    </tr>\n",
       "  </tbody>\n",
       "</table>\n",
       "</div>"
      ],
      "text/plain": [
       "                                              sentence  label\n",
       "995  I think food should have flavor and texture an...      0\n",
       "996                           Appetite instantly gone.      0\n",
       "997  Overall I was not impressed and would not go b...      0\n",
       "998  The whole experience was underwhelming, and I ...      0\n",
       "999  Then, as if I hadn't wasted enough of my life ...      0"
      ]
     },
     "execution_count": 13,
     "metadata": {},
     "output_type": "execute_result"
    }
   ],
   "source": [
    "df.tail()"
   ]
  },
  {
   "cell_type": "code",
   "execution_count": 14,
   "id": "b6fe5493",
   "metadata": {},
   "outputs": [],
   "source": [
    "from sklearn.model_selection import train_test_split\n",
    "kalimat = df['sentence'].values\n",
    "y = df['label'].values\n",
    "kalimat_latih, kalimat_test, y_latih, y_test = train_test_split(kalimat, y, test_size=0.2)"
   ]
  },
  {
   "cell_type": "code",
   "execution_count": 20,
   "id": "f0b92a92",
   "metadata": {},
   "outputs": [],
   "source": [
    "from tensorflow.keras.preprocessing.text import Tokenizer\n",
    "from tensorflow.keras.preprocessing.sequence import pad_sequences\n",
    " \n",
    "tokenizer = Tokenizer(num_words=250, oov_token='x')\n",
    "tokenizer.fit_on_texts(kalimat_latih) \n",
    "tokenizer.fit_on_texts(kalimat_test)\n",
    " \n",
    "sekuens_latih = tokenizer.texts_to_sequences(kalimat_latih)\n",
    "sekuens_test = tokenizer.texts_to_sequences(kalimat_test)\n",
    " \n",
    "padded_latih = pad_sequences(sekuens_latih) \n",
    "padded_test = pad_sequences(sekuens_test)"
   ]
  },
  {
   "cell_type": "code",
   "execution_count": 21,
   "id": "893c3fc5",
   "metadata": {},
   "outputs": [],
   "source": [
    "import tensorflow as tf\n",
    "model = tf.keras.Sequential([\n",
    "    tf.keras.layers.Embedding(250, 16, input_length=20),\n",
    "    tf.keras.layers.GlobalAveragePooling1D(),\n",
    "    tf.keras.layers.Dense(24, activation='relu'),\n",
    "    tf.keras.layers.Dense(1, activation='sigmoid')\n",
    "])\n",
    "model.compile(loss='binary_crossentropy',optimizer='adam',metrics=['accuracy'])"
   ]
  },
  {
   "cell_type": "code",
   "execution_count": 24,
   "id": "09012fc1",
   "metadata": {},
   "outputs": [
    {
     "name": "stdout",
     "output_type": "stream",
     "text": [
      "Epoch 1/30\n"
     ]
    },
    {
     "ename": "ValueError",
     "evalue": "in user code:\n\n    File \"C:\\Users\\Azhar Rizky Zulma\\anaconda3\\lib\\site-packages\\keras\\engine\\training.py\", line 878, in train_function  *\n        return step_function(self, iterator)\n    File \"C:\\Users\\Azhar Rizky Zulma\\anaconda3\\lib\\site-packages\\keras\\engine\\training.py\", line 867, in step_function  **\n        outputs = model.distribute_strategy.run(run_step, args=(data,))\n    File \"C:\\Users\\Azhar Rizky Zulma\\anaconda3\\lib\\site-packages\\keras\\engine\\training.py\", line 860, in run_step  **\n        outputs = model.train_step(data)\n    File \"C:\\Users\\Azhar Rizky Zulma\\anaconda3\\lib\\site-packages\\keras\\engine\\training.py\", line 808, in train_step\n        y_pred = self(x, training=True)\n    File \"C:\\Users\\Azhar Rizky Zulma\\anaconda3\\lib\\site-packages\\keras\\utils\\traceback_utils.py\", line 67, in error_handler\n        raise e.with_traceback(filtered_tb) from None\n    File \"C:\\Users\\Azhar Rizky Zulma\\anaconda3\\lib\\site-packages\\keras\\engine\\input_spec.py\", line 263, in assert_input_compatibility\n        raise ValueError(f'Input {input_index} of layer \"{layer_name}\" is '\n\n    ValueError: Input 0 of layer \"sequential_2\" is incompatible with the layer: expected shape=(None, 20), found shape=(None, 31)\n",
     "output_type": "error",
     "traceback": [
      "\u001b[1;31m---------------------------------------------------------------------------\u001b[0m",
      "\u001b[1;31mValueError\u001b[0m                                Traceback (most recent call last)",
      "\u001b[1;32mC:\\Users\\AZHARR~1\\AppData\\Local\\Temp/ipykernel_12988/3663707901.py\u001b[0m in \u001b[0;36m<module>\u001b[1;34m\u001b[0m\n\u001b[0;32m      1\u001b[0m \u001b[0mnum_epochs\u001b[0m \u001b[1;33m=\u001b[0m \u001b[1;36m30\u001b[0m\u001b[1;33m\u001b[0m\u001b[1;33m\u001b[0m\u001b[0m\n\u001b[1;32m----> 2\u001b[1;33m history = model.fit(padded_latih, y_latih, epochs=num_epochs, batch_size=512,\n\u001b[0m\u001b[0;32m      3\u001b[0m                     validation_data=(padded_test, y_test), verbose=2)\n",
      "\u001b[1;32m~\\anaconda3\\lib\\site-packages\\keras\\utils\\traceback_utils.py\u001b[0m in \u001b[0;36merror_handler\u001b[1;34m(*args, **kwargs)\u001b[0m\n\u001b[0;32m     65\u001b[0m     \u001b[1;32mexcept\u001b[0m \u001b[0mException\u001b[0m \u001b[1;32mas\u001b[0m \u001b[0me\u001b[0m\u001b[1;33m:\u001b[0m  \u001b[1;31m# pylint: disable=broad-except\u001b[0m\u001b[1;33m\u001b[0m\u001b[1;33m\u001b[0m\u001b[0m\n\u001b[0;32m     66\u001b[0m       \u001b[0mfiltered_tb\u001b[0m \u001b[1;33m=\u001b[0m \u001b[0m_process_traceback_frames\u001b[0m\u001b[1;33m(\u001b[0m\u001b[0me\u001b[0m\u001b[1;33m.\u001b[0m\u001b[0m__traceback__\u001b[0m\u001b[1;33m)\u001b[0m\u001b[1;33m\u001b[0m\u001b[1;33m\u001b[0m\u001b[0m\n\u001b[1;32m---> 67\u001b[1;33m       \u001b[1;32mraise\u001b[0m \u001b[0me\u001b[0m\u001b[1;33m.\u001b[0m\u001b[0mwith_traceback\u001b[0m\u001b[1;33m(\u001b[0m\u001b[0mfiltered_tb\u001b[0m\u001b[1;33m)\u001b[0m \u001b[1;32mfrom\u001b[0m \u001b[1;32mNone\u001b[0m\u001b[1;33m\u001b[0m\u001b[1;33m\u001b[0m\u001b[0m\n\u001b[0m\u001b[0;32m     68\u001b[0m     \u001b[1;32mfinally\u001b[0m\u001b[1;33m:\u001b[0m\u001b[1;33m\u001b[0m\u001b[1;33m\u001b[0m\u001b[0m\n\u001b[0;32m     69\u001b[0m       \u001b[1;32mdel\u001b[0m \u001b[0mfiltered_tb\u001b[0m\u001b[1;33m\u001b[0m\u001b[1;33m\u001b[0m\u001b[0m\n",
      "\u001b[1;32m~\\anaconda3\\lib\\site-packages\\tensorflow\\python\\framework\\func_graph.py\u001b[0m in \u001b[0;36mautograph_handler\u001b[1;34m(*args, **kwargs)\u001b[0m\n\u001b[0;32m   1127\u001b[0m           \u001b[1;32mexcept\u001b[0m \u001b[0mException\u001b[0m \u001b[1;32mas\u001b[0m \u001b[0me\u001b[0m\u001b[1;33m:\u001b[0m  \u001b[1;31m# pylint:disable=broad-except\u001b[0m\u001b[1;33m\u001b[0m\u001b[1;33m\u001b[0m\u001b[0m\n\u001b[0;32m   1128\u001b[0m             \u001b[1;32mif\u001b[0m \u001b[0mhasattr\u001b[0m\u001b[1;33m(\u001b[0m\u001b[0me\u001b[0m\u001b[1;33m,\u001b[0m \u001b[1;34m\"ag_error_metadata\"\u001b[0m\u001b[1;33m)\u001b[0m\u001b[1;33m:\u001b[0m\u001b[1;33m\u001b[0m\u001b[1;33m\u001b[0m\u001b[0m\n\u001b[1;32m-> 1129\u001b[1;33m               \u001b[1;32mraise\u001b[0m \u001b[0me\u001b[0m\u001b[1;33m.\u001b[0m\u001b[0mag_error_metadata\u001b[0m\u001b[1;33m.\u001b[0m\u001b[0mto_exception\u001b[0m\u001b[1;33m(\u001b[0m\u001b[0me\u001b[0m\u001b[1;33m)\u001b[0m\u001b[1;33m\u001b[0m\u001b[1;33m\u001b[0m\u001b[0m\n\u001b[0m\u001b[0;32m   1130\u001b[0m             \u001b[1;32melse\u001b[0m\u001b[1;33m:\u001b[0m\u001b[1;33m\u001b[0m\u001b[1;33m\u001b[0m\u001b[0m\n\u001b[0;32m   1131\u001b[0m               \u001b[1;32mraise\u001b[0m\u001b[1;33m\u001b[0m\u001b[1;33m\u001b[0m\u001b[0m\n",
      "\u001b[1;31mValueError\u001b[0m: in user code:\n\n    File \"C:\\Users\\Azhar Rizky Zulma\\anaconda3\\lib\\site-packages\\keras\\engine\\training.py\", line 878, in train_function  *\n        return step_function(self, iterator)\n    File \"C:\\Users\\Azhar Rizky Zulma\\anaconda3\\lib\\site-packages\\keras\\engine\\training.py\", line 867, in step_function  **\n        outputs = model.distribute_strategy.run(run_step, args=(data,))\n    File \"C:\\Users\\Azhar Rizky Zulma\\anaconda3\\lib\\site-packages\\keras\\engine\\training.py\", line 860, in run_step  **\n        outputs = model.train_step(data)\n    File \"C:\\Users\\Azhar Rizky Zulma\\anaconda3\\lib\\site-packages\\keras\\engine\\training.py\", line 808, in train_step\n        y_pred = self(x, training=True)\n    File \"C:\\Users\\Azhar Rizky Zulma\\anaconda3\\lib\\site-packages\\keras\\utils\\traceback_utils.py\", line 67, in error_handler\n        raise e.with_traceback(filtered_tb) from None\n    File \"C:\\Users\\Azhar Rizky Zulma\\anaconda3\\lib\\site-packages\\keras\\engine\\input_spec.py\", line 263, in assert_input_compatibility\n        raise ValueError(f'Input {input_index} of layer \"{layer_name}\" is '\n\n    ValueError: Input 0 of layer \"sequential_2\" is incompatible with the layer: expected shape=(None, 20), found shape=(None, 31)\n"
     ]
    }
   ],
   "source": [
    "num_epochs = 30\n",
    "history = model.fit(padded_latih, y_latih, epochs=num_epochs,\n",
    "                    validation_data=(padded_test, y_test), verbose=2)"
   ]
  },
  {
   "cell_type": "code",
   "execution_count": null,
   "id": "86b50698",
   "metadata": {},
   "outputs": [],
   "source": []
  }
 ],
 "metadata": {
  "kernelspec": {
   "display_name": "Python 3 (ipykernel)",
   "language": "python",
   "name": "python3"
  },
  "language_info": {
   "codemirror_mode": {
    "name": "ipython",
    "version": 3
   },
   "file_extension": ".py",
   "mimetype": "text/x-python",
   "name": "python",
   "nbconvert_exporter": "python",
   "pygments_lexer": "ipython3",
   "version": "3.9.7"
  }
 },
 "nbformat": 4,
 "nbformat_minor": 5
}
